Workbook
Name _ZA10115: #REF!
Name _ZA10121: #REF!
Name _ZA10122: #REF!
Name _ZA10123: #REF!
Name _ZA10124: #REF!
Name _ZA10125: #REF!
Name _ZA10132: #REF!
Name _ZA10133: #REF!
Name _ZA10137: #REF!
Name _ZA10139: #REF!
Name _ZA10143: #REF!
Name _ZA10153: #REF!
Name _ZA10154: #REF!
Name _ZA10155: #REF!
Name _ZA10157: #REF!
Name _ZA10208: #REF!
Name _ZA10209: #REF!
Name _ZA10213: #REF!
Name _ZA10217: #REF!
Name _ZA10223: #REF!
Name _za10230: #REF!
Name _za10231: #REF!
Name _ZA10306: #REF!
Name _ZA10315: #REF!
Name _ZA10317: #REF!
Name _za10318: #REF!
Name _ZA10320: #REF!
Name _ZA10324: #REF!
Name _ZA10326: #REF!
Name _ZA10334: #REF!
Name _ZA10337: #REF!
Name _ZA10339: #REF!
Name _ZA10340: #REF!
Name _ZA10341: #REF!
Name _ZA10345: #REF!
Name _ZA10346: #REF!
Name _ZA10351: #REF!
Name _ZA10353: #REF!
Name _ZA10354: #REF!
Name _ZA10355: #REF!
Name _ZA10375: #REF!
Name _ZA10381: #REF!
Name _ZA10382: #REF!
Name _ZA10384: #REF!
Name _ZA10387: #REF!
Name _ZA10395: #REF!
Name _ZA10398: #REF!
Name _ZA10399: #REF!
Name _ZA10408: #REF!
Name _za10409: #REF!
Name _ZA10413: #REF!
Name _ZA10414: #REF!
Name _ZA10416: #REF!
Name _ZA10417: #REF!
Name _ZA10418: #REF!
Name _ZA10419: #REF!
Name _ZA10421: #REF!
Name _ZA10429: #REF!
Name _za10439: #REF!
Name _ZA10445: #REF!

Sheet Master
A2: 1.Location Name: Akua Madrasa Quarter, Mymensingh. | B2: Enter Location Area | C2: Khilkhet Amtola, Hazibari, House - Kha-53, Khilkhet, Dhaka -1229
A3: Address: Akua Madrasa Quarter, Hajibari Fulbaria Road, Mymensingh. | B3: P&P (Y OR N) | C3: N
A4: 2.Location District - Mymensingh | B4: FR/OWN | C4: FR
A5: 3.P&P (Y OR N) - N | B5: Location Size Range -SFT | C5: 1550
A6: 4.Location Size Range (1100 SFT) | B6: Population Density (H/M/L) | C6: H | G6: Mr. Kaushik | H6: Regional Head
A7: 5.Population Density - H | B7: Income Level (A/B/C) | C7: A | E7: Opened by | G7: Mr. Shadhin | H7: Regional Head
A8: 6.Income Level - A | B8: Commercial Hub | E8: Md. Hasanuzzaman | F8: Head Of Business Expansion | G8: Mr. Azim | H8: Regional Head
A9: 7.Location Type - Residential Hub | B9: Dhaka | E9: Mr. Shamsuzzaman | F9: Assistant Director, Business Expansion | G9: Mr. Emran | H9: Regional Head
A10: 8.Front Fasia Long - 24 feet | B10: Long-feet | C10: 25 | E10: Mr. Mohammad Zaherul Islam | F10: Assistant Director, Business Expansion | G10: Mr. Mahbub | H10: Regional Head
A11: 9.MONTHLY RENT - 45 K | B11: Projected Per Day Sales for this new location | C11: 60000 | E11: Mr. Abdullah Al Masum | F11: Head Of Business Expansion | G11: Mr. Kabir | H11: Regional Head
A12: 10.ADVANCE - 6 Lac | B12: MONTHLY RENT | C12: 61000 | E12: Mr. Lutful Kabir Munna | F12: Head Of Business Expansion | G12: Mr. Riaz | H12: Regional Head
A13: 11.Sales Given By - Mr. Mamun (Sales Daily: 45,000 TK ) | B13: ADVANCE | C13: 1200000 | E13: Mr. Fakhrul Alamgir | F13: Head Of Business Expansion | G13: Mr. Sunny | H13: Regional Head
A14: 12.Opened by (Mr. Abu Sayem) | B14: Outbound Transport | C14: 10000 | E14: Mr. Abu Sayem Mohammad Al Azad | F14: Head Of Business Expansion | G14: Mr. Yusuf | H14: Regional Head
A15: 13.Google Location: https://maps.app.goo.gl/7f4Sa7PpExz26h596?g_st=ac | B15: Sales Given By | C15: Mr. Ersadul Haque | E15: Mr. Mahbub | F15: Regional Head | G15: Ms. Qarin | H15: Regional Head
B16: Opened by | C16: Mr. Fakhrul Alamgir | G16: Mr.Ranjan | H16: Regional Head
B17: Opened by Designation | C17: =VLOOKUP(C16,E8:F15,2,) -> Head Of Business Expansion
B18: Existing No. of outlets around 1 KM radius | C18: 0
A20: (1)Location Name:
A21: (2)Location District-
A22: (3)FR/OWN-
A23: (4)P&P (Y OR N):-
A24: (5)Location Size Range:-….......SFT
A25: (6)Population Density (H/M/L):-
A26: (7)Income Level (A/B/C):-
A27: (8)Location Type:
A28: (9)Front Fasia Long-
A29: (10)MONTHLY RENT:-
A30: (11)ADVANCE:-
A31: (12)Sales Given By:-Mr. …... -- (Sales Daily : …...../- )
... A33: Existing No. of outlets around 1 KM radius

Sheet Stock WRT.O_Final
B4: Status | C4: Sales Revenue | D4: Stock write off (Prov.) | E4: Stock write off (Prov.)%
B5: Barishal FR Non-PNP | C5: 908674821 | D5: 3747205.1 | E5: =D5/C5 -> 0.004123813
B6: Barishal OWN PNP | C6: 108325208 | D6: 670902.24 | E6: =D6/C6 -> 0.0061934082
B7: Chattogram FR Non-PNP | C7: 1549026526 | D7: 7275302.2 | E7: =D7/C7 -> 0.0046966931
B8: Chattogram FR PNP | C8: 92204996 | D8: 313385.28 | E8: =D8/C8 -> 0.0033987885
B9: Chattogram OWN Non-PNP | C9: 132376746 | D9: 614629.69 | E9: =D9/C9 -> 0.0046430337
B10: Chattogram OWN PNP | C10: 1339491716 | D10: 5939811.2 | E10: =D10/C10 -> 0.004434377
B11: Dhaka FR Non-PNP | C11: 6708526730 | D11: 32474401 | E11: =D11/C11 -> 0.0048407649
B12: Dhaka FR PNP | C12: 1223538654 | D12: 9114594.8 | E12: =D12/C12 -> 0.0074493722
B13: Dhaka OWN Non-PNP | C13: 243678729 | D13: 932225.52 | E13: =D13/C13 -> 0.0038256335
B14: Dhaka OWN PNP | C14: 4971522470 | D14: 23651948 | E14: =D14/C14 -> 0.004757486
B15: DhakaGBUD OWN PNP | C15: 5291302809 | D15: 25693923 | E15: =D15/C15 -> 0.0048558784
B16: Khulna FR Non-PNP | C16: 681218749 | D16: 3447527.8 | E16: =D16/C16 -> 0.0050608234
... B28: Sylhet OWN PNP | C28: 827375791 | D28: 4192059.5 | E28: =D28/C28 -> 0.0050666935

Sheet Stock WRT.O
F1: inventory gap | G1: =SUBTOTAL(9,G3:G7966) -> 27604407075 | H1: =SUBTOTAL(9,H3:H7966) -> 4.5675019e+09 | I1: =SUBTOTAL(9,I3:I7966) -> 1.3536976e+08 | J1: =H1/G1 -> 0.16546278 | K1: =I1/G1 -> 0.0049039185
A2: CODE | B2: District | C2: Division | D2: PNP Non PNP status | E2: Status | F2: Feasibility Calc | G2: Sales Revenue | H2: GP | I2: Stock write off (Prov.) | J2: GP% | K2: Stock write off (Prov.)% | L2: GP% | M2: Stock write off (Prov.)%
A3: C001 | B3: Chattogram | C3: Chattogram | D3: PNP | E3: OWN | F3: =CONCATENATE(C3," ",E3," ",D3) -> Chattogram OWN PNP | G3: 11539330 | H3: 1969677.4 | I3: 120945.08 | L3: =(H3/G3)*100 -> 17.069253 | M3: =(I3/G3)*100 -> 1.0481118
A4: C009 | B4: Chattogram | C4: Chattogram | D4: PNP | E4: OWN | F4: =CONCATENATE(C4," ",E4," ",D4) -> Chattogram OWN PNP | G4: 16656264 | H4: 3033316.3 | I4: 64543.47 | L4: =(H4/G4)*100 -> 18.211265 | M4: =(I4/G4)*100 -> 0.38750268
A5: C011 | B5: Cumilla | C5: Chattogram | D5: PNP | E5: OWN | F5: =CONCATENATE(C5," ",E5," ",D5) -> Chattogram OWN PNP | G5: 11423303 | H5: 1972918.2 | I5: 0 | L5: =(H5/G5)*100 -> 17.270996 | M5: =(I5/G5)*100 -> 0
A6: C013 | B6: Cumilla | C6: Chattogram | D6: PNP | E6: OWN | F6: =CONCATENATE(C6," ",E6," ",D6) -> Chattogram OWN PNP | G6: 27426999 | H6: 5257223.1 | I6: 97281.735 | L6: =(H6/G6)*100 -> 19.168058 | M6: =(I6/G6)*100 -> 0.35469333
A7: C015 | B7: Chattogram | C7: Chattogram | D7: PNP | E7: OWN | F7: =CONCATENATE(C7," ",E7," ",D7) -> Chattogram OWN PNP | G7: 11154136 | H7: 1908185.1 | I7: 330768.94 | L7: =(H7/G7)*100 -> 17.107422 | M7: =(I7/G7)*100 -> 2.9654375
A8: C016 | B8: Cumilla | C8: Chattogram | D8: Non-PNP | E8: OWN | F8: =CONCATENATE(C8," ",E8," ",D8) -> Chattogram OWN Non-PNP | G8: 2857188 | H8: 508590.43 | I8: 11428.752 | L8: =(H8/G8)*100 -> 17.800384 | M8: =(I8/G8)*100 -> 0.4
A9: C017 | B9: Feni | C9: Chattogram | D9: PNP | E9: OWN | F9: =CONCATENATE(C9," ",E9," ",D9) -> Chattogram OWN PNP | G9: 9024395 | H9: 1670629.2 | I9: 34423.28 | L9: =(H9/G9)*100 -> 18.512367 | M9: =(I9/G9)*100 -> 0.38144696
A10: C018 | B10: Chattogram | C10: Chattogram | D10: PNP | E10: OWN | F10: =CONCATENATE(C10," ",E10," ",D10) -> Chattogram OWN PNP | G10: 6808373 | H10: 1189576.6 | I10: 0 | L10: =(H10/G10)*100 -> 17.47226 | M10: =(I10/G10)*100 -> 0
A11: C019 | B11: Cox's Bazar | C11: Chattogram | D11: Non-PNP | E11: OWN | F11: =CONCATENATE(C11," ",E11," ",D11) -> Chattogram OWN Non-PNP | G11: 3193573 | H11: 651214.53 | I11: 12774.292 | L11: =(H11/G11)*100 -> 20.391409 | M11: =(I11/G11)*100 -> 0.4
A12: C020 | B12: Brahmanbaria | C12: Chattogram | D12: Non-PNP | E12: OWN | F12: =CONCATENATE(C12," ",E12," ",D12) -> Chattogram OWN Non-PNP | G12: 3971632 | H12: 747317.23 | I12: 15886.528 | L12: =(H12/G12)*100 -> 18.816377 | M12: =(I12/G12)*100 -> 0.4
A13: C021 | B13: Cox's Bazar | C13: Chattogram | D13: PNP | E13: OWN | F13: =CONCATENATE(C13," ",E13," ",D13) -> Chattogram OWN PNP | G13: 9728809 | H13: 1714786.5 | I13: 38392.395 | L13: =(H13/G13)*100 -> 17.625863 | M13: =(I13/G13)*100 -> 0.39462585
A14: D002 | B14: Dhaka | C14: Dhaka | D14: PNP | E14: OWN | F14: =CONCATENATE(C14," ",E14," ",D14) -> Dhaka OWN PNP | G14: 3715386 | H14: 672033.71 | I14: 15502.49 | L14: =(H14/G14)*100 -> 18.087857 | M14: =(I14/G14)*100 -> 0.41725113
... A70: B004 | B70: Barishal | C70: Barishal | D70: PNP | E70: OWN | F70: =CONCATENATE(C70," ",E70," ",D70) -> Barishal OWN PNP | G70: 8600171 | H70: 1433123.2 | I70: 33614.165 | L70: =(H70/G70)*100 -> 16.663892 | M70: =(I70/G70)*100 -> 0.39085461
A71: K006 | B71: Khulna | C71: Khulna | D71: Non-PNP | E71: OWN | F71: =CONCATENATE(C71," ",E71," ",D71) -> Khulna OWN Non-PNP | G71: 5909133 | H71: 974360.45 | L71: =(H71/G71)*100 -> 16.489059 | M71: =(I71/G71)*100 -> 0
A72: K007 | B72: Khulna | C72: Khulna | D72: PNP | E72: OWN | F72: =CONCATENATE(C72," ",E72," ",D72) -> Khulna OWN PNP | G72: 5439059 | H72: 868608.52 | I72: 23937.065 | L72: =(H72/G72)*100 -> 15.969831 | M72: =(I72/G72)*100 -> 0.4400957
A73: K008 | B73: Khulna | C73: Khulna | D73: PNP | E73: OWN | F73: =CONCATENATE(C73," ",E73," ",D73) -> Khulna OWN PNP | G73: 4895825 | H73: 785540.47 | I73: 21707.905 | L73: =(H73/G73)*100 -> 16.045109 | M73: =(I73/G73)*100 -> 0.44339626
A74: R008 | B74: Bogura | C74: Rajshahi | D74: PNP | E74: OWN | F74: =CONCATENATE(C74," ",E74," ",D74) -> Rajshahi OWN PNP | G74: 10935478 | H74: 1792668.2 | I74: 39900.37 | L74: =(H74/G74)*100 -> 16.39314 | M74: =(I74/G74)*100 -> 0.36487084
A75: R009 | B75: Joypurhat | C75: Rajshahi | D75: Non-PNP | E75: OWN | F75: =CONCATENATE(C75," ",E75," ",D75) -> Rajshahi OWN Non-PNP | G75: 2862881 | H75: 540561.7 | I75: 2.1827873e-11 | L75: =(H75/G75)*100 -> 18.881738 | M75: =(I75/G75)*100 -> 7.6244429e-16
A76: R010 | B76: Naogaon | C76: Rajshahi | D76: Non-PNP | E76: OWN | F76: =CONCATENATE(C76," ",E76," ",D76) -> Rajshahi OWN Non-PNP | G76: 3850115 | H76: 696489.97 | L76: =(H76/G76)*100 -> 18.090108 | M76: =(I76/G76)*100 -> 0
A77: R011 | B77: Rajshahi | C77: Rajshahi | D77: PNP | E77: OWN | F77: =CONCATENATE(C77," ",E77," ",D77) -> Rajshahi OWN PNP | G77: 7692364 | H77: 1221016.9 | I77: 30926.27 | L77: =(H77/G77)*100 -> 15.873104 | M77: =(I77/G77)*100 -> 0.40203857
A78: S001 | B78: Sylhet | C78: Sylhet | D78: PNP | E78: OWN | F78: =CONCATENATE(C78," ",E78," ",D78) -> Sylhet OWN PNP | G78: 14173786 | H78: 2384696.4 | I78: 162133.89 | L78: =(H78/G78)*100 -> 16.824696 | M78: =(I78/G78)*100 -> 1.1438997
A79: S002 | B79: Sylhet | C79: Sylhet | D79: PNP | E79: OWN | F79: =CONCATENATE(C79," ",E79," ",D79) -> Sylhet OWN PNP | G79: 7236201 | H79: 1279415.4 | I79: 22396.948 | L79: =(H79/G79)*100 -> 17.680762 | M79: =(I79/G79)*100 -> 0.30951253
A80: S003 | B80: Sylhet | C80: Sylhet | D80: PNP | E80: OWN | F80: =CONCATENATE(C80," ",E80," ",D80) -> Sylhet OWN PNP | G80: 6067286 | H80: 982450.21 | I80: 0 | L80: =(H80/G80)*100 -> 16.192581 | M80: =(I80/G80)*100 -> 0
A81: S006 | B81: Sylhet | C81: Sylhet | D81: PNP | E81: OWN | F81: =CONCATENATE(C81," ",E81," ",D81) -> Sylhet OWN PNP | G81: 14497811 | H81: 2576229 | I81: 53552.59 | L81: =(H81/G81)*100 -> 17.769779 | M81: =(I81/G81)*100 -> 0.36938397
A82: S007 | B82: Sylhet | C82: Sylhet | D82: PNP | E82: OWN | F82: =CONCATENATE(C82," ",E82," ",D82) -> Sylhet OWN PNP | G82: 6051094 | H82: 984409.35 | I82: 80987.116 | L82: =(H82/G82)*100 -> 16.268287 | M82: =(I82/G82)*100 -> 1.338388
A83: S008 | B83: Sylhet | C83: Sylhet | D83: PNP | E83: OWN | F83: =CONCATENATE(C83," ",E83," ",D83) -> Sylhet OWN PNP | G83: 11174878 | H83: 1941708.6 | I83: 35961.95 | L83: =(H83/G83)*100 -> 17.375658 | M83: =(I83/G83)*100 -> 0.32181067
A84: S009 | B84: Moulvibazar | C84: Sylhet | D84: PNP | E84: OWN | F84: =CONCATENATE(C84," ",E84," ",D84) -> Sylhet OWN PNP | G84: 5851452 | H84: 1038132.6 | I84: 63597.779 | L84: =(H84/G84)*100 -> 17.741452 | M84: =(I84/G84)*100 -> 1.0868718
A85: C012 | B85: Brahmanbaria | C85: Chattogram | D85: Non-PNP | E85: FR | F85: =CONCATENATE(C85," ",E85," ",D85) -> Chattogram FR Non-PNP | G85: 2212323 | H85: 388037.73 | I85: 8849.292 | L85: =(H85/G85)*100 -> 17.539831 | M85: =(I85/G85)*100 -> 0.4
A86: D079 | B86: Dhaka | C86: Dhaka | D86: Non-PNP | E86: FR | F86: =CONCATENATE(C86," ",E86," ",D86) -> Dhaka FR Non-PNP | G86: 3610102 | H86: 603507.49 | I86: 14440.408 | L86: =(H86/G86)*100 -> 16.717187 | M86: =(I86/G86)*100 -> 0.4
A87: D080 | B87: Dhaka | C87: Dhaka | D87: Non-PNP | E87: FR | F87: =CONCATENATE(C87," ",E87," ",D87) -> Dhaka FR Non-PNP | G87: 2000247 | H87: 333069.81 | I87: 8000.988 | L87: =(H87/G87)*100 -> 16.651434 | M87: =(I87/G87)*100 -> 0.4
A88: D081 | B88: Dhaka | C88: Dhaka | D88: Non-PNP | E88: FR | F88: =CONCATENATE(C88," ",E88," ",D88) -> Dhaka FR Non-PNP | G88: 4511067 | H88: 746105.66 | I88: 18044.268 | L88: =(H88/G88)*100 -> 16.53945 | M88: =(I88/G88)*100 -> 0.4
... A657: F705 | B657: Dhaka | C657: Dhaka | D657: Non-PNP | E657: FR | F657: =CONCATENATE(C657," ",E657," ",D657) -> Dhaka FR Non-PNP | G657: 1608083 | H657: 277469.05 | I657: 6432.332 | L657: =(H657/G657)*100 -> 17.254647 | M657: =(I657/G657)*100 -> 0.4
A658: F706 | B658: Cumilla | C658: Chattogram | D658: Non-PNP | E658: FR | F658: =CONCATENATE(C658," ",E658," ",D658) -> Chattogram FR Non-PNP | G658: 528001 | H658: 104574.33 | L658: =(H658/G658)*100 -> 19.805707 | M658: =(I658/G658)*100 -> 0
A659: F709 | B659: Gaibandha | C659: Rangpur | D659: Non-PNP | E659: FR | F659: =CONCATENATE(C659," ",E659," ",D659) -> Rangpur FR Non-PNP | G659: 625133 | H659: 118519.52 | L659: =(H659/G659)*100 -> 18.959088 | M659: =(I659/G659)*100 -> 0
A660: F710 | B660: Dhaka | C660: Dhaka | D660: Non-PNP | E660: FR | F660: =CONCATENATE(C660," ",E660," ",D660) -> Dhaka FR Non-PNP | G660: 811384 | H660: 142434.3 | L660: =(H660/G660)*100 -> 17.554487 | M660: =(I660/G660)*100 -> 0
A661: F711 | B661: Sylhet | C661: Sylhet | D661: Non-PNP | E661: FR | F661: =CONCATENATE(C661," ",E661," ",D661) -> Sylhet FR Non-PNP | G661: 4543 | H661: 992.39811 | L661: =(H661/G661)*100 -> 21.844554 | M661: =(I661/G661)*100 -> 0
A662: F712 | B662: Tangail | C662: Dhaka | D662: Non-PNP | E662: FR | F662: =CONCATENATE(C662," ",E662," ",D662) -> Dhaka FR Non-PNP | G662: 2241 | H662: 84.684535 | L662: =(H662/G662)*100 -> 3.7788726 | M662: =(I662/G662)*100 -> 0
A663: F715 | B663: Sylhet | C663: Sylhet | D663: Non-PNP | E663: FR | F663: =CONCATENATE(C663," ",E663," ",D663) -> Sylhet FR Non-PNP | G663: 18919 | H663: 3143.8083 | L663: =(H663/G663)*100 -> 16.617201 | M663: =(I663/G663)*100 -> 0
...

Sheet Sales forecasting tools
A1: Sales Forecasting Format
A2: SL | B2: Description | C2: Weightage | D2: Target | E2: Measuring Tools | F2: Answers | G2: Marking Criteria | H2: Mark | I2: Achievement | AC2: GP% | AD2: Basket | AE2: Stock write off (Prov.)%
A3: =ROW()-2 -> 1 | B3: Location Size Range | E3: SFT | F3: =Master!C5 -> 1550 | N3: =VLOOKUP(F3,$X$3:$Y$20597,2,0) -> 1501 TO 1800 | X3: 300 | Y3: 0 TO 800 | AB3: Chattogram FR Non-PNP | AC3: 0.16528831 | AD3: 485.08971 | AE3: 0.0046966931
A4: =ROW()-2 -> 2 | B4: Population Density/Residential Area | C4: 0.18 | D4: 100 | E4: High/Medium/Low | F4: =Master!C6 -> H | H4: =IF(F4="H",100,IF(F4="M",70,IF(F4="L",50,0))) -> 100 | I4: =(H4/D4)*C4 -> 0.18 | K4: =F8 -> M | N4: =F4 -> H | X4: 301 | Y4: 0 TO 800 | AB4: Dhaka FR Non-PNP | AC4: 0.15969476 | AD4: 426.75837 | AE4: 0.0048407649
A5: =ROW()-2 -> 3 | B5: House Rent/Income Level | C5: 0.15 | D5: 100 | E5: A/B/C | F5: =Master!C7 -> A | H5: =IF(F5="A",100,IF(F5="B",70,IF(F5="C",50,0))) -> 100 | I5: =(H5/D5)*C5 -> 0.15 | J5: Location Type | N5: =F5 -> A | X5: 302 | Y5: 0 TO 800
A6: =ROW()-2 -> 4 | B6: Location Type | C6: 0.18 | D6: 100 | E6: =Master!B8 -> Commercial Hub | H6: =_xlfn.XLOOKUP(E6,$T$6:$T$13,$U$6:$U$13,0) -> 85 | I6: =(H6/D6)*C6 -> 0.153 | N6: =E6 -> Commercial Hub | T6: Commercial Hub | U6: 85 | X6: 303 | Y6: 0 TO 800 | AB6: Barishal FR Non-PNP | AC6: 0.15601993 | AD6: 416.77936 | AE6: 0.004123813
A7: =ROW()-2 -> 5 | B7: Avg. Sales of Departmental Stores/Competitor Store | C7: 0.08 | D7: 100 | E7: Avg per Day Sales | F7: 25000 | H7: =IF(F7=0,0,IF(F7>=45000,100,IF(F7>=35000,80,IF(F7>=25000,60,IF(F7>=15000,40,20))))) -> 60 | I7: =(H7/D7)*C7 -> 0.048 | N7: =C19 -> Dhaka | T7: High Street W Residential Block | U7: 90 | X7: 304 | Y7: 0 TO 800 | AB7: Mymensingh FR Non-PNP | AC7: 0.15572779 | AD7: 418.87151 | AE7: 0.0041957585
A8: =ROW()-2 -> 6 | B8: Road Status | C8: 0.08 | D8: 100 | E8: Main Road/Support Road | F8: M | H8: =IF(F8="M",100,IF(F8="S",80,0)) -> 100 | I8: =(H8/D8)*C8 -> 0.08 | N8: =C20 -> N | T8: Within the Mahalla | U8: 65 | X8: 305 | Y8: 0 TO 800 | AB8: Sylhet FR PNP | AC8: 0.14642073 | AD8: 451.98979 | AE8: 0.0044435185
A9: =ROW()-2 -> 7 | B9: Mosque/Mandir/Girza | C9: 0.08 | D9: 100 | E9: How Many | F9: 2 | H9: =IF(F9>=2,100,IF(F9=1,80,0)) -> 100 | I9: =(H9/D9)*C9 -> 0.08 | N9: =IF(C19="Dhaka","Inside Dhaka","Outside Dhaka") -> Inside Dhaka | T9: Industrial | U9: 60 | X9: 306 | Y9: 0 TO 800 | AB9: Chattogram FR PNP | AC9: 0.1748718 | AD9: 573.29022 | AE9: 0.0033987885
A10: =ROW()-2 -> 8 | B10: School/College/University | C10: 0.07 | D10: 100 | E10: How Many | F10: 2 | H10: =IF(F10>=2,100,IF(F10=1,80,0)) -> 100 | I10: =(H10/D10)*C10 -> 0.07 | T10: High Street | U10: 70 | X10: 307 | Y10: 0 TO 800 | AB10: Rajshahi FR Non-PNP | AC10: 0.15744786 | AD10: 440.13984 | AE10: 0.0065464264
A11: =ROW()-2 -> 9 | B11: Bank/Office/ATM BOOTH | C11: 0.06 | D11: 100 | E11: How Many | F11: 2 | H11: =IF(F11>=2,100,IF(F11=1,80,0)) -> 100 | I11: =(H11/D11)*C11 -> 0.06 | T11: Gated Community | U11: 100 | X11: 308 | Y11: 0 TO 800 | AB11: Khulna FR Non-PNP | AC11: 0.16189873 | AD11: 410.65205 | AE11: 0.0050608234
A12: =ROW()-2 -> 10 | B12: CNG, Bus, Train Station/ Pick & Drop | C12: 0.04 | D12: 100 | E12: Y/N | F12: Y | H12: =IF(F12="Y",100,0) -> 100 | I12: =(H12/D12)*C12 -> 0.04 | N12: =CONCATENATE(N3,N4,N8) -> 1501 TO 1800HN | T12: Inside the Mall | U12: 55 | X12: 309 | Y12: 0 TO 800 | AB12: Rangpur FR PNP | AC12: 0.15913809 | AD12: 820.18193 | AE12: 0.0039854998
A13: =ROW()-2 -> 11 | B13: Front Fasia | C13: 0.02 | D13: 100 | E13: Long-feet | F13: =Master!C10 -> 25 | H13: =IF(F13=0,0,IF(F13>=20,100,80)) -> 100 | I13: =(H13/D13)*C13 -> 0.02 | T13: High Street W Institutions | U13: 75 | X13: 310 | Y13: 0 TO 800 | AB13: Rangpur FR Non-PNP | AC13: 0.15282818 | AD13: 427.30991 | AE13: 0.0049513318
A14: =ROW()-2 -> 12 | B14: Signboard Visibility | C14: 0.04 | D14: 100 | E14: High/Medium | F14: H | H14: =IF(F14="H",100,IF(F14="M",80)) -> 100 | I14: =(H14/D14)*C14 -> 0.04 | N14: =CONCATENATE(N3,N4,N8) -> 1501 TO 1800HN | X14: 311 | Y14: 0 TO 800 | AB14: Khulna FR PNP | AC14: 0.14902038 | AD14: 726.30333 | AE14: 0.004041028
A15: =ROW()-2 -> 13 | B15: Hotel & Restaurant & Hospital/ Club | C15: 0.02 | D15: 100 | E15: How Many | F15: 3 | H15: =IF(F15>=3,100,IF(F15=2,80,0)) -> 100 | I15: =(H15/D15)*C15 -> 0.02 | X15: 312 | Y15: 0 TO 800 | AB15: Rajshahi OWN Non-PNP | AC15: 0.17797353 | AD15: 531.42859
B16: Total | C16: =SUM(C4:C15) -> 1 | E16: Total | I16: =SUM(I4:I15) -> 0.941 | X16: 313 | Y16: 0 TO 800 | AB16: Dhaka FR PNP | AC16: 0.15766804 | AD16: 414.02385 | AE16: 0.0074493722
E17: Category wise Sales Mix | X17: 314 | Y17: 0 TO 800 | AB17: Rajshahi FR PNP | AC17: 0.16 | AD17: 368.04767 | AE17: 0.0055
B18: Enter Location Area | C18: =Master!C2 -> Khilkhet Amtola, Hazibari, House - Kha-53, Khilkhet, Dhaka -1229 | E18: Category | H18: Per Day Sales | I18: Monthly Sales | X18: 315 | Y18: 0 TO 800 | AB18: Sylhet FR Non-PNP | AC18: 0.15249915 | AD18: 277.68537 | AE18: 0.0049894139
B19: Enter Division Name | C19: =Master!B9 -> Dhaka | D19: 4 | E19: Baby Care | H19: =(IF($C$20="Y",U21,V21))*$H$37 -> 808.35627 | I19: =H19*30 -> 24250.688 | N19: =Master!C4 -> FR | X19: 316 | Y19: 0 TO 800
B20: P&P (Y OR N) | C20: =Master!C3 -> N | D20: 6 | E20: Baby Food | H20: =(IF($C$20="Y",U22,V22))*$H$37 -> 702.91272 | I20: =H20*30 -> 21087.382 | N20: =IF(C20="Y","PNP","Non-PNP") -> Non-PNP | S20: FR PNP | T20: FR NON-PNP | U20: FR PNP Con% | V20: FR NON-PNP Con% | X20: 317 | Y20: 0 TO 800 | AB20: Barishal OWN PNP | AC20: 0.15686241 | AD20: 565.56883 | AE20: 0.0061934082
B21: GP% | C21: =VLOOKUP($N$21,$AB$3:$AC$30,2,0) -> 0.15969476 | D21: 8 | E21: Beverage & Tobacco | H21: =(IF($C$20="Y",U23,V23))*$H$37 -> 3167.9267 | I21: =H21*30 -> 95037.8 | N21: =CONCATENATE(C19," ",N19," ",N20) -> Dhaka FR Non-PNP | R21: Baby Care | S21: 67721.612 | T21: 21262.176 | U21: =IFERROR(S21/$S$39,0) -> 0.01001768 | V21: =IFERROR(T21/$T$39,0) -> 0.013472604 | X21: 318 | Y21: 0 TO 800 | AB21: Chattogram OWN PNP | AC21: 0.1638435 | AD21: 865.0753 | AE21: 0.004434377
B22: Dhaka/out of Dhaka | C22: =IF(C19="Dhaka","Dhaka","Out Of Dhaka") -> Dhaka | D22: 12 | E22: Dairy | H22: =(IF($C$20="Y",U24,V24))*$H$37 -> 4270.3409 | I22: =H22*30 -> 128110.23 | R22: Baby Food | S22: 45340.417 | T22: 18488.697 | U22: =IFERROR(S22/$S$39,0) -> 0.0067069548 | V22: =IFERROR(T22/$T$39,0) -> 0.011715212 | X22: 319 | Y22: 0 TO 800 | AB22: Chattogram OWN Non-PNP | AC22: 0.18723579 | AD22: 492.64322 | AE22: 0.0046430337
B23: Sales (Reference) | C23: =VLOOKUP($B$43,'Reference (LocationType & Dens '!$E:$H,2,0)/30 -> 119126.78 | D23: 24 | E23: Home Care | H23: =(IF($C$20="Y",U25,V25))*$H$37 -> 4814.3045 | I23: =H23*30 -> 144429.14 | R23: Beverage & Tobacco | S23: 293387.48 | T23: 83325.902 | U23: =IFERROR(S23/$S$39,0) -> 0.043399172 | V23: =IFERROR(T23/$T$39,0) -> 0.052798778 | X23: 320 | Y23: 0 TO 800 | AB23: Dhaka OWN PNP | AC23: 0.16750762 | AD23: 722.70586 | AE23: 0.004757486
B24: FF (Reference)/Day | C24: =VLOOKUP($B$43,'Reference (LocationType & Dens '!$E:$H,3,0)/30 -> 217.24375 | D24: 30 | E24: Kitchen Additives | H24: =(IF($C$20="Y",U26,V26))*$H$37 -> 3156.0873 | I24: =H24*30 -> 94682.62 | R24: Dairy | S24: 455189.69 | T24: 112322.68 | U24: =IFERROR(S24/$S$39,0) -> 0.067333669 | V24: =IFERROR(T24/$T$39,0) -> 0.071172348 | X24: 321 | Y24: 0 TO 800 | AB24: Dhaka GBUD OWN PNP | AC24: 0.17314745 | AD24: 1006.6521 | AE24: 0.005
B25: Basket (Reference) | C25: =C23/C24 -> 548.35539 | D25: 34 | E25: Packaged Foods | H25: =(IF($C$20="Y",U27,V27))*$H$37 -> 15440.716 | I25: =H25*30 -> 463221.49 | R25: Home Care | S25: 419172.22 | T25: 126630.54 | U25: =IFERROR(S25/$S$39,0) -> 0.062005806 | V25: =IFERROR(T25/$T$39,0) -> 0.080238408 | X25: 322 | Y25: 0 TO 800 | AB25: Dhaka OWN Non-PNP | AC25: 0.16518962 | AD25: 487.88106 | AE25: 0.0038256335
B26: Profit (Reference) | C26: =VLOOKUP($B$43,'Reference (LocationType & Dens '!$E:$I,5,0) -> 257639.5 | E26: Personal Care | H26: =(IF($C$20="Y",U28,V28))*$H$37 -> 8345.0713 | I26: =H26*30 -> 250352.14 | R26: Kitchen Additives | S26: 297874.87 | T26: 83014.493 | U26: =IFERROR(S26/$S$39,0) -> 0.044062967 | V26: =IFERROR(T26/$T$39,0) -> 0.052601456 | X26: 323 | Y26: 0 TO 800 | AB26: Khulna OWN Non-PNP | AC26: 0.15726401 | AD26: 602.31421 | AE26: 0.003492622
D27: 38 | R27: Packaged Foods | S27: 1398193.8 | T27: 406136.81 | U27: =IFERROR(S27/$S$39,0) -> 0.20682701 | V27: =IFERROR(T27/$T$39,0) -> 0.25734527 | X27: 324 | Y27: 0 TO 800 | AB27: Khulna OWN PNP | AC27: 0.14245785 | AD27: 524.92641 | AE27: 0.0035921925
B28: Projected Basket Size (Reference) | C28: =VLOOKUP($N$21,$AB$3:$AD$30,3,0) -> 426.75837 | D28: 10 | E28: Commodities | H28: =(IF($C$20="Y",U30,V30))*$H$37 -> 16321.108 | I28: =H28*30 -> 489633.24 | R28: Personal Care | S28: 768455.95 | T28: 219500.22 | U28: =IFERROR(S28/$S$39,0) -> 0.1136734 | V28: =IFERROR(T28/$T$39,0) -> 0.13908452 | X28: 325 | Y28: 0 TO 800 | AB28: Rajshahi OWN PNP | AC28: 0.15853757 | AD28: 635.38947 | AE28: 0.005524236
B29: Projected Per Day Sales for this new location | C29: =Master!C11 -> 60000 | D29: 14 | E29: Electronics & Appl | H29: =(IF($C$20="Y",U31,V31))*$H$37 -> 620.14259 | I29: =H29*30 -> 18604.278 | X29: 326 | Y29: 0 TO 800
B30: Projected Daily Footfall for this new location | C30: =C29/C28 -> 140.59478 | D30: 16 | E30: Gift & Toys | H30: =(IF($C$20="Y",U32,V32))*$H$37 -> 506.64627 | I30: =H30*30 -> 15199.388 | R30: Commodities | S30: 1316426.5 | T30: 429293.73 | U30: =IFERROR(S30/$S$39,0) -> 0.19473163 | V30: =IFERROR(T30/$T$39,0) -> 0.27201846 | X30: 327 | Y30: 0 TO 800 | AB30: Sylhet OWN PNP | AC30: 0.15802485 | AD30: 774.63847 | AE30: 0.0050666935
B31: Existing No. of outlets around 1 KM radius | D31: 20 | E31: Home Accessories | H31: =(IF($C$20="Y",U33,V33))*$H$37 -> 1061.3033 | I31: =H31*30 -> 31839.1 | R31: Electronics & Appl | S31: 70182.755 | T31: 16311.596 | U31: =IFERROR(S31/$S$39,0) -> 0.010381743 | V31: =IFERROR(T31/$T$39,0) -> 0.01033571 | X31: 328 | Y31: 0 TO 800
D32: 22 | E32: Home Appliance | H32: =(IF($C$20="Y",U34,V34))*$H$37 -> 410.11046 | I32: =H32*30 -> 12303.314 | R32: Gift & Toys | S32: 41069.459 | T32: 13326.305 | U32: =IFERROR(S32/$S$39,0) -> 0.0060751758 | V32: =IFERROR(T32/$T$39,0) -> 0.0084441045 | X32: 329 | Y32: 0 TO 800
D33: 44 | E33: Stationeries | H33: =(IF($C$20="Y",U35,V35))*$H$37 -> 228.22896 | I33: =H33*30 -> 6846.8687 | R33: Home Accessories | S33: 118616.29 | T33: 27915.437 | U33: =IFERROR(S33/$S$39,0) -> 0.017546245 | V33: =IFERROR(T33/$T$39,0) -> 0.017688389 | X33: 330 | Y33: 0 TO 800
D34: 32 | E34: Life Style | H34: =(IF($C$20="Y",U36,V36))*$H$37 -> 70.707615 | I34: =H34*30 -> 2121.2285 | R34: Home Appliance | S34: 27205.62 | T34: 10787.126 | U34: =IFERROR(S34/$S$39,0) -> 0.0040243755 | V34: =IFERROR(T34/$T$39,0) -> 0.0068351743 | X34: 331 | Y34: 0 TO 800
D35: 36 | E35: Perishables | H35: =(IF($C$20="Y",U37,V37))*$H$37 -> 0 | I35: =H35*30 -> 0 | R35: Stationeries | S35: 22702.811 | T35: 6003.101 | U35: =IFERROR(S35/$S$39,0) -> 0.0033583 | V35: =IFERROR(T35/$T$39,0) -> 0.0038038159 | X35: 332 | Y35: 0 TO 800
D36: 40 | E36: Protein | H36: =(IF($C$20="Y",U38,V38))*$H$37 -> 76.03702 | I36: =H36*30 -> 2281.1106 | R36: Life Style | S36: 22075.085 | T36: 1859.8208 | U36: =IFERROR(S36/$S$39,0) -> 0.0032654441 | V36: =IFERROR(T36/$T$39,0) -> 0.0011784603 | X36: 333 | Y36: 0 TO 800
H37: =C29 -> 60000 | I37: =H37*30 -> 1800000 | R37: Perishables | S37: 262461.61 | T37: 0 | U37: =IFERROR(S37/$S$39,0) -> 0.038824481 | V37: =IFERROR(T37/$T$39,0) -> 0 | X37: 334 | Y37: 0 TO 800
R38: Protein | S38: 1134133 | T38: 2000 | U38: =IFERROR(S38/$S$39,0) -> 0.16776596 | V38: =IFERROR(T38/$T$39,0) -> 0.0012672837 | X38: 335 | Y38: 0 TO 800
S39: =SUM(S21:S38) -> 6760209.2 | T39: =SUM(T21:T38) -> 1578178.6 | U39: =SUM(U21:U38) -> 1 | V39: =SUM(V21:V38) -> 1 | X39: 336 | Y39: 0 TO 800
X40: 337 | Y40: 0 TO 800
...

Sheet Sheet3
A1: 0 TO 800
A2: 801 TO 1000
A3: 1001 TO 1200
A4: 1201 TO 1500
A5: 1501 TO 1800
A6: 1801 TO 2000
A7: 2001 TO 2500
A8: 2501 TO 3000
A9: 3001 TO 5000
A10: 5001 TO 8000
A11: 8001 TO 10000
A12: 10001 & ABOVE

Sheet Reference (LocationType & Dens 
B3: Location Type | C3: Population Density | D3: Division | E3: Unique | F3: AVG Sales | G3: AVG FF | H3: AVG BS | I3: AVG Profit
B4: Commercial Hub | C4: H | D4: Barishal | E4: Commercial HubHBarishal | F4: 4387198 | G4: 7620 | H4: 575.74777 | I4: 187701.59
B5: Commercial Hub | C5: H | D5: Chattogram | E5: Commercial HubHChattogram | F5: 3002746.1 | G5: 5077.7143 | H5: 591.35784 | I5: 231129.94
B6: Commercial Hub | C6: H | D6: Dhaka | E6: Commercial HubHDhaka | F6: 3573803.4 | G6: 6517.3125 | H6: 548.35539 | I6: 257639.5
B7: Commercial Hub | C7: H | D7: DhakaGBUD | E7: Commercial HubHDhakaGBUD | F7: 1887336 | G7: 5767 | H7: 327.26478 | I7: 89633.599
B8: Commercial Hub | C8: H | D8: Mymensingh | E8: Commercial HubHMymensingh | F8: 2873429.3 | G8: 5657 | H8: 507.94225 | I8: 204543.76
B9: Commercial Hub | C9: H | D9: Rajshahi | E9: Commercial HubHRajshahi | F9: 4299581.4 | G9: 7577 | H9: 567.45169 | I9: 345932.7
B10: Commercial Hub | C10: H | D10: Rangpur | E10: Commercial HubHRangpur | F10: 2622345.3 | G10: 4846.6667 | H10: 541.06162 | I10: 68957.558
B11: Commercial Hub | C11: L | D11: Barishal | E11: Commercial HubLBarishal | F11: 774963.5 | G11: 2387.25 | H11: 324.62603 | I11: -181.49326
B12: Commercial Hub | C12: L | D12: Chattogram | E12: Commercial HubLChattogram | F12: 1240578.9 | G12: 2583.625 | H12: 480.16987 | I12: 65745.572
B13: Commercial Hub | C13: L | D13: Dhaka | E13: Commercial HubLDhaka | F13: 1247453.8 | G13: 3001.0952 | H13: 415.66617 | I13: 57830.306
B14: Commercial Hub | C14: L | D14: Khulna | E14: Commercial HubLKhulna | F14: 1709327 | G14: 3937.75 | H14: 434.08723 | I14: 114852.05
B15: Commercial Hub | C15: L | D15: Mymensingh | E15: Commercial HubLMymensingh | F15: 1033326.6 | G15: 2525 | H15: 409.23826 | I15: 20861.937
... B117: Within the Mahalla | C117: M | D117: Rangpur | E117: Within the MahallaMRangpur | F117: 1460791.5 | G117: 3528.3333 | H117: 414.01743 | I117: 22961.877

Sheet INFORMATION
A3: BUSINESS FEASIBILITY INFORMATION
A4: PROJECT NAME | B4: ='Sales forecasting tools'!C18 -> Khilkhet Amtola, Hazibari, House - Kha-53, Khilkhet, Dhaka -1229
D5: MANPOWER ALLOCATION
A6: SFT | B6: ='Sales forecasting tools'!F3 -> 1550 | E6: Qty | F6: Salary | G6: Total Amount
A7: GP SHARE | B7: 0.4 | D7: OM-Parmanent | E7: =IF(UPPER(TRIM($B$14))="Y",INDEX(MANPOWER!$C$25:$AF$38,MATCH(D7,MANPOWER!$B$25:$B$38,0),MATCH($B$9,{0,1500000,1900000,2200000,2500000,2800000,3100000,3400000,3700000,4000000,4300000,4600000,4900000,5200000,5500000,5800000,6100000,6400000,6700000,7000000,7300000,7600000,7900000,8200000,8500000,8800000,9100000,9400000,9700000,10000000},1)),INDEX(MANPOWER!$C$4:$AF$17,MATCH(D7,MANPOWER!$B$4:$B$17,0),MATCH($B$9,{0,1500000,1900000,2200000,2500000,2800000,3100000,3400000,3700000,4000000,4300000,4600000,4900000,5200000,5500000,5800000,6100000,6400000,6700000,7000000,7300000,7600000,7900000,8200000,8500000,8800000,9100000,9400000,9700000,10000000},1))) -> 1 | F7: 23000 | G7: =F7*E7 -> 23000
A8: SALES PER DAY | B8: ='Sales forecasting tools'!C29 -> 60000 | D8: ICMO-Parmanent | E8: =IF(UPPER(TRIM($B$14))="Y",INDEX(MANPOWER!$C$25:$AF$38,MATCH(D8,MANPOWER!$B$25:$B$38,0),MATCH($B$9,{0,1500000,1900000,2200000,2500000,2800000,3100000,3400000,3700000,4000000,4300000,4600000,4900000,5200000,5500000,5800000,6100000,6400000,6700000,7000000,7300000,7600000,7900000,8200000,8500000,8800000,9100000,9400000,9700000,10000000},1)),INDEX(MANPOWER!$C$4:$AF$17,MATCH(D8,MANPOWER!$B$4:$B$17,0),MATCH($B$9,{0,1500000,1900000,2200000,2500000,2800000,3100000,3400000,3700000,4000000,4300000,4600000,4900000,5200000,5500000,5800000,6100000,6400000,6700000,7000000,7300000,7600000,7900000,8200000,8500000,8800000,9100000,9400000,9700000,10000000},1))) -> 0 | F8: 15000 | G8: =F8*E8 -> 0 | J8: Y | K8: 430000
A9: MONTH SALES | B9: =IFERROR(B8*30,0) -> 1800000 | D9: Duty officer | E9: =IF(UPPER(TRIM($B$14))="Y",INDEX(MANPOWER!$C$25:$AF$38,MATCH(D9,MANPOWER!$B$25:$B$38,0),MATCH($B$9,{0,1500000,1900000,2200000,2500000,2800000,3100000,3400000,3700000,4000000,4300000,4600000,4900000,5200000,5500000,5800000,6100000,6400000,6700000,7000000,7300000,7600000,7900000,8200000,8500000,8800000,9100000,9400000,9700000,10000000},1)),INDEX(MANPOWER!$C$4:$AF$17,MATCH(D9,MANPOWER!$B$4:$B$17,0),MATCH($B$9,{0,1500000,1900000,2200000,2500000,2800000,3100000,3400000,3700000,4000000,4300000,4600000,4900000,5200000,5500000,5800000,6100000,6400000,6700000,7000000,7300000,7600000,7900000,8200000,8500000,8800000,9100000,9400000,9700000,10000000},1))) -> 1 | F9: 12000 | G9: =F9*E9 -> 12000 | J9: N | K9: 330000
A10: GP% | B10: ='Sales forecasting tools'!C21 -> 0.15969476
A11: BASKET SIZE | B11: ='Sales forecasting tools'!C28 -> 426.75837
A12: FF/Day | B12: ='Sales forecasting tools'!C30 -> 140.59478 | D12: CG | E12: =IF(UPPER(TRIM($B$14))="Y",INDEX(MANPOWER!$C$25:$AF$38,MATCH(D12,MANPOWER!$B$25:$B$38,0),MATCH($B$9,{0,1500000,1900000,2200000,2500000,2800000,3100000,3400000,3700000,4000000,4300000,4600000,4900000,5200000,5500000,5800000,6100000,6400000,6700000,7000000,7300000,7600000,7900000,8200000,8500000,8800000,9100000,9400000,9700000,10000000},1)),INDEX(MANPOWER!$C$4:$AF$17,MATCH(D12,MANPOWER!$B$4:$B$17,0),MATCH($B$9,{0,1500000,1900000,2200000,2500000,2800000,3100000,3400000,3700000,4000000,4300000,4600000,4900000,5200000,5500000,5800000,6100000,6400000,6700000,7000000,7300000,7600000,7900000,8200000,8500000,8800000,9100000,9400000,9700000,10000000},1))) -> 2 | F12: 8000 | G12: =F12*E12 -> 16000
A13: OTHER INCOME % | B13: 0.03 | D13: COMMODITY | E13: =IF(UPPER(TRIM($B$14))="Y",INDEX(MANPOWER!$C$25:$AF$38,MATCH(D13,MANPOWER!$B$25:$B$38,0),MATCH($B$9,{0,1500000,1900000,2200000,2500000,2800000,3100000,3400000,3700000,4000000,4300000,4600000,4900000,5200000,5500000,5800000,6100000,6400000,6700000,7000000,7300000,7600000,7900000,8200000,8500000,8800000,9100000,9400000,9700000,10000000},1)),INDEX(MANPOWER!$C$4:$AF$17,MATCH(D13,MANPOWER!$B$4:$B$17,0),MATCH($B$9,{0,1500000,1900000,2200000,2500000,2800000,3100000,3400000,3700000,4000000,4300000,4600000,4900000,5200000,5500000,5800000,6100000,6400000,6700000,7000000,7300000,7600000,7900000,8200000,8500000,8800000,9100000,9400000,9700000,10000000},1))) -> 0 | F13: 8000 | G13: =F13*E13 -> 0
A14: P&P (Y/N) | B14: ='Sales forecasting tools'!C20 -> N | D14: PROTEIN | E14: =IF(UPPER(TRIM($B$14))="Y",INDEX(MANPOWER!$C$25:$AF$38,MATCH(D14,MANPOWER!$B$25:$B$38,0),MATCH($B$9,{0,1500000,1900000,2200000,2500000,2800000,3100000,3400000,3700000,4000000,4300000,4600000,4900000,5200000,5500000,5800000,6100000,6400000,6700000,7000000,7300000,7600000,7900000,8200000,8500000,8800000,9100000,9400000,9700000,10000000},1)),INDEX(MANPOWER!$C$4:$AF$17,MATCH(D14,MANPOWER!$B$4:$B$17,0),MATCH($B$9,{0,1500000,1900000,2200000,2500000,2800000,3100000,3400000,3700000,4000000,4300000,4600000,4900000,5200000,5500000,5800000,6100000,6400000,6700000,7000000,7300000,7600000,7900000,8200000,8500000,8800000,9100000,9400000,9700000,10000000},1))) -> 0 | F14: 10000 | G14: =F14*E14 -> 0
A15: MONTHLY RENT | B15: =Master!C12 -> 61000 | D15: PERISHABLES | E15: =IF(UPPER(TRIM($B$14))="Y",INDEX(MANPOWER!$C$25:$AF$38,MATCH(D15,MANPOWER!$B$25:$B$38,0),MATCH($B$9,{0,1500000,1900000,2200000,2500000,2800000,3100000,3400000,3700000,4000000,4300000,4600000,4900000,5200000,5500000,5800000,6100000,6400000,6700000,7000000,7300000,7600000,7900000,8200000,8500000,8800000,9100000,9400000,9700000,10000000},1)),INDEX(MANPOWER!$C$4:$AF$17,MATCH(D15,MANPOWER!$B$4:$B$17,0),MATCH($B$9,{0,1500000,1900000,2200000,2500000,2800000,3100000,3400000,3700000,4000000,4300000,4600000,4900000,5200000,5500000,5800000,6100000,6400000,6700000,7000000,7300000,7600000,7900000,8200000,8500000,8800000,9100000,9400000,9700000,10000000},1))) -> 0 | F15: 8000 | G15: =F15*E15 -> 0
A16: ADVANCE | B16: =Master!C13 -> 1200000 | D16: GM & LIFESTYLE | E16: =IF(UPPER(TRIM($B$14))="Y",INDEX(MANPOWER!$C$25:$AF$38,MATCH(D16,MANPOWER!$B$25:$B$38,0),MATCH($B$9,{0,1500000,1900000,2200000,2500000,2800000,3100000,3400000,3700000,4000000,4300000,4600000,4900000,5200000,5500000,5800000,6100000,6400000,6700000,7000000,7300000,7600000,7900000,8200000,8500000,8800000,9100000,9400000,9700000,10000000},1)),INDEX(MANPOWER!$C$4:$AF$17,MATCH(D16,MANPOWER!$B$4:$B$17,0),MATCH($B$9,{0,1500000,1900000,2200000,2500000,2800000,3100000,3400000,3700000,4000000,4300000,4600000,4900000,5200000,5500000,5800000,6100000,6400000,6700000,7000000,7300000,7600000,7900000,8200000,8500000,8800000,9100000,9400000,9700000,10000000},1))) -> 0 | F16: 8000 | G16: =F16*E16 -> 0
A17: CEP VALUE | B17: =VLOOKUP(B14,$J$8:$K$9,2,) -> 330000 | D17: POS | E17: =IF(UPPER(TRIM($B$14))="Y",INDEX(MANPOWER!$C$25:$AF$38,MATCH(D17,MANPOWER!$B$25:$B$38,0),MATCH($B$9,{0,1500000,1900000,2200000,2500000,2800000,3100000,3400000,3700000,4000000,4300000,4600000,4900000,5200000,5500000,5800000,6100000,6400000,6700000,7000000,7300000,7600000,7900000,8200000,8500000,8800000,9100000,9400000,9700000,10000000},1)),INDEX(MANPOWER!$C$4:$AF$17,MATCH(D17,MANPOWER!$B$4:$B$17,0),MATCH($B$9,{0,1500000,1900000,2200000,2500000,2800000,3100000,3400000,3700000,4000000,4300000,4600000,4900000,5200000,5500000,5800000,6100000,6400000,6700000,7000000,7300000,7600000,7900000,8200000,8500000,8800000,9100000,9400000,9700000,10000000},1))) -> 1 | F17: 9500 | G17: =F17*E17 -> 9500
A18: AREA OUT OF DHAKA (Y/N) | B18: =IF('Sales forecasting tools'!C19="Dhaka","N","Y") -> N | D18: PORTER | E18: =IF(UPPER(TRIM($B$14))="Y",INDEX(MANPOWER!$C$25:$AF$38,MATCH(D18,MANPOWER!$B$25:$B$38,0),MATCH($B$9,{0,1500000,1900000,2200000,2500000,2800000,3100000,3400000,3700000,4000000,4300000,4600000,4900000,5200000,5500000,5800000,6100000,6400000,6700000,7000000,7300000,7600000,7900000,8200000,8500000,8800000,9100000,9400000,9700000,10000000},1)),INDEX(MANPOWER!$C$4:$AF$17,MATCH(D18,MANPOWER!$B$4:$B$17,0),MATCH($B$9,{0,1500000,1900000,2200000,2500000,2800000,3100000,3400000,3700000,4000000,4300000,4600000,4900000,5200000,5500000,5800000,6100000,6400000,6700000,7000000,7300000,7600000,7900000,8200000,8500000,8800000,9100000,9400000,9700000,10000000},1))) -> 0 | F18: 7500 | G18: =F18*E18 -> 0
A19: DECORATION COST | B19: =MAX(1500000,IF(B14="N",B6*1000,B6*1000+2000000)) -> 1550000 | D19: BSM | E19: =IF(UPPER(TRIM($B$14))="Y",INDEX(MANPOWER!$C$25:$AF$38,MATCH(D19,MANPOWER!$B$25:$B$38,0),MATCH($B$9,{0,1500000,1900000,2200000,2500000,2800000,3100000,3400000,3700000,4000000,4300000,4600000,4900000,5200000,5500000,5800000,6100000,6400000,6700000,7000000,7300000,7600000,7900000,8200000,8500000,8800000,9100000,9400000,9700000,10000000},1)),INDEX(MANPOWER!$C$4:$AF$17,MATCH(D19,MANPOWER!$B$4:$B$17,0),MATCH($B$9,{0,1500000,1900000,2200000,2500000,2800000,3100000,3400000,3700000,4000000,4300000,4600000,4900000,5200000,5500000,5800000,6100000,6400000,6700000,7000000,7300000,7600000,7900000,8200000,8500000,8800000,9100000,9400000,9700000,10000000},1))) -> 0 | F19: 11000 | G19: =F19*E19 -> 0
D20: BK STR | E20: =IF(UPPER(TRIM($B$14))="Y",INDEX(MANPOWER!$C$25:$AF$38,MATCH(D20,MANPOWER!$B$25:$B$38,0),MATCH($B$9,{0,1500000,1900000,2200000,2500000,2800000,3100000,3400000,3700000,4000000,4300000,4600000,4900000,5200000,5500000,5800000,6100000,6400000,6700000,7000000,7300000,7600000,7900000,8200000,8500000,8800000,9100000,9400000,9700000,10000000},1)),INDEX(MANPOWER!$C$4:$AF$17,MATCH(D20,MANPOWER!$B$4:$B$17,0),MATCH($B$9,{0,1500000,1900000,2200000,2500000,2800000,3100000,3400000,3700000,4000000,4300000,4600000,4900000,5200000,5500000,5800000,6100000,6400000,6700000,7000000,7300000,7600000,7900000,8200000,8500000,8800000,9100000,9400000,9700000,10000000},1))) -> 0 | F20: 8000 | G20: =F20*E20 -> 0
D21: SECURITY | E21: =IF(UPPER(TRIM($B$14))="Y",INDEX(MANPOWER!$C$25:$AF$38,MATCH(D21,MANPOWER!$B$25:$B$38,0),MATCH($B$9,{0,1500000,1900000,2200000,2500000,2800000,3100000,3400000,3700000,4000000,4300000,4600000,4900000,5200000,5500000,5800000,6100000,6400000,6700000,7000000,7300000,7600000,7900000,8200000,8500000,8800000,9100000,9400000,9700000,10000000},1)),INDEX(MANPOWER!$C$4:$AF$17,MATCH(D21,MANPOWER!$B$4:$B$17,0),MATCH($B$9,{0,1500000,1900000,2200000,2500000,2800000,3100000,3400000,3700000,4000000,4300000,4600000,4900000,5200000,5500000,5800000,6100000,6400000,6700000,7000000,7300000,7600000,7900000,8200000,8500000,8800000,9100000,9400000,9700000,10000000},1))) -> 0 | F21: 11500 | G21: =F21*E21 -> 0
D22: CLEANER | E22: =IF(UPPER(TRIM($B$14))="Y",INDEX(MANPOWER!$C$25:$AF$38,MATCH(D22,MANPOWER!$B$25:$B$38,0),MATCH($B$9,{0,1500000,1900000,2200000,2500000,2800000,3100000,3400000,3700000,4000000,4300000,4600000,4900000,5200000,5500000,5800000,6100000,6400000,6700000,7000000,7300000,7600000,7900000,8200000,8500000,8800000,9100000,9400000,9700000,10000000},1)),INDEX(MANPOWER!$C$4:$AF$17,MATCH(D22,MANPOWER!$B$4:$B$17,0),MATCH($B$9,{0,1500000,1900000,2200000,2500000,2800000,3100000,3400000,3700000,4000000,4300000,4600000,4900000,5200000,5500000,5800000,6100000,6400000,6700000,7000000,7300000,7600000,7900000,8200000,8500000,8800000,9100000,9400000,9700000,10000000},1))) -> 0 | F22: 7500 | G22: =F22*E22 -> 0
E23: =SUM(E7:E22) -> 5 | G23: =SUM(G7:G22) -> 60500

Sheet AUTO GENERATED FEASIBILITY
A1: =INFORMATION!B4 -> Khilkhet Amtola, Hazibari, House - Kha-53, Khilkhet, Dhaka -1229 | C1: Prepare Date | E1: =TODAY() -> 46295
B2: Number/ Percentage | C2: 1st Month | D2: 2nd Month | E2: 3rd Month | G2: 1st year | H2: 2nd year | I2: 3rd year | J2: 4th year | K2: 5th year | L2: Total
A3: Fixed asset investment( CEP Value) | C3: =INFORMATION!B17 -> 330000 | G3: =C3 -> 330000
A4: Average Stock | C4: =C6*1650 -> 2557500 | D4: =C4 -> 2557500 | E4: =D4 -> 2557500 | G4: =E4 -> 2557500 | H4: =G4 -> 2557500 | I4: =H4 -> 2557500 | J4: =I4 -> 2557500 | K4: =J4 -> 2557500
A5: Stock Holding Days | C5: =(C4*30)/(C10*(1-C14)) -> 50.725615 | D5: =(D4*30)/(D10*(1-D14)) -> 50.725615 | E5: =(E4*30)/(E10*(1-E14)) -> 50.725615 | G5: =(G4*365)/(G10*(1-G14)) -> 51.430137 | H5: =(H4*365)/(H10*(1-H14)) -> 46.029319 | I5: =(I4*365)/(I10*(1-I14)) -> 41.944906 | J5: =(J4*365)/(J10*(1-J14)) -> 38.223142 | K5: =(K4*365)/(K10*(1-K14)) -> 35.476844
A6: Area in SFT | C6: ='Sales forecasting tools'!F3 -> 1550 | D6: =C6 -> 1550 | E6: =D6 -> 1550 | G6: =E6 -> 1550 | H6: =G6 -> 1550 | I6: =H6 -> 1550 | J6: =I6 -> 1550 | K6: =J6 -> 1550
A7: Day Average Foot Fall | C7: =C9/C8 -> 140.59478 | D7: =D9/D8 -> 140.59478 | E7: =E9/E8 -> 140.59478 | G7: =AVERAGE(C7:E7) -> 140.59478 | H7: =H9/H8 -> 151.40977 | I7: =I9/I8 -> 160.14495 | J7: =J9/J8 -> 169.38408 | K7: =K9/K8 -> 175.89885
A8: Average Basket Size | C8: =INFORMATION!B11 -> 426.75837 | D8: =C8 -> 426.75837 | E8: =D8 -> 426.75837 | G8: =G9/G7 -> 426.75837 | H8: =G8*1.04 -> 443.8287 | I8: =H8*1.04 -> 461.58185 | J8: =I8*1.04 -> 480.04512 | K8: =J8*1.04 -> 499.24693
A9: Day Average Sales | C9: =INFORMATION!B8 -> 60000 | D9: =D10/30 -> 60000 | E9: =E10/30 -> 60000 | G9: =G10/360 -> 60000 | H9: =H10/360 -> 67200 | I9: =I10/360 -> 73920 | J9: =J10/360 -> 81312 | K9: =K10/360 -> 87816.96
A10: Sales Revenue | C10: =C9*30 -> 1800000 | D10: =C10 -> 1800000 | E10: =D10 -> 1800000 | G10: =C10*12 -> 21600000 | H10: =G10*1.12 -> 24192000 | I10: =H10*1.1 -> 26611200 | J10: =I10*1.1 -> 29272320 | K10: =J10*1.08 -> 31614106 | L10: =SUM(G10:K10) -> 1.3328963e+08
A12: COGS | C12: =C10-C13 -> 1512549.4 | D12: =D10-D13 -> 1512549.4 | E12: =E10-E13 -> 1512549.4 | G12: =G10-G13 -> 18150593 | H12: =H10-H13 -> 20280280 | I12: =I10-I13 -> 22255086 | J12: =J10-J13 -> 24422050 | K12: =K10-K13 -> 26312586 | L12: =SUM(G12:K12) -> 1.114206e+08
A13: GPV | C13: =C10*C14 -> 287450.56 | D13: =D10*D14 -> 287450.56 | E13: =E10*E14 -> 287450.56 | G13: =G10*G14 -> 3449406.7 | H13: =H10*H14 -> 3911719.5 | I13: =I10*I14 -> 4356113.9 | J13: =J10*J14 -> 4850269.9 | K13: =K10*K14 -> 5301519.7 | L13: =SUM(G13:K13) -> 21869030
A14: GP % | C14: =INFORMATION!B10 -> 0.15969476 | D14: =C14 -> 0.15969476 | E14: =D14 -> 0.15969476 | G14: =E14 -> 0.15969476 | H14: =G14+0.2% -> 0.16169476 | I14: =H14+0.2% -> 0.16369476 | J14: =I14+0.2% -> 0.16569476 | K14: =J14+0.2% -> 0.16769476 | L14: =L13/L10 -> 0.16407151
A15: Space Rent & Other Income | B15: =INFORMATION!B13 -> 0.03 | C15: =$B$15*C10 -> 54000 | D15: =$B$15*D10 -> 54000 | E15: =$B$15*E10 -> 54000 | G15: =$B$15*G10 -> 648000 | H15: =$B$15*H10 -> 725760 | I15: =$B$15*I10 -> 798336 | J15: =$B$15*J10 -> 878169.6 | K15: =$B$15*K10 -> 948423.17 | L15: =SUM(G15:K15) -> 3998688.8
A16: TOTAL INCOME | C16: =C15+C13 -> 341450.56 | D16: =D15+D13 -> 341450.56 | E16: =E15+E13 -> 341450.56 | G16: =G15+G13 -> 4097406.7 | H16: =H15+H13 -> 4637479.5 | I16: =I15+I13 -> 5154449.9 | J16: =J15+J13 -> 5728439.5 | K16: =K15+K13 -> 6249942.9 | L16: =SUM(G16:K16) -> 25867718
A18: Franchisee Commission | B18: =INFORMATION!B7 -> 0.4 | C18: =($B$18*C16) -> 136580.22 | D18: =($B$18*D16) -> 136580.22 | E18: =($B$18*E16) -> 136580.22 | G18: =($B$18*G16) -> 1638962.7 | H18: =($B$18*H16) -> 1854991.8 | I18: =($B$18*I16) -> 2061779.9 | J18: =($B$18*J16) -> 2291375.8 | K18: =($B$18*K16) -> 2499977.1 | L18: =SUM(G18:K18) -> 10347087
A19: Rent | L19: =SUM(G19:K19) -> 0
A20: Outlet staff salary (Contractual) | B20: =SUM(INFORMATION!E9:E20) -> 4 | C20: =SUM(INFORMATION!G9:G20) -> 37500 | D20: =C20 -> 37500 | E20: =D20 -> 37500 | G20: =SUM(C20:E20)*4 -> 450000 | H20: =G20+G20*8% -> 486000 | I20: =H20+H20*8% -> 524880 | J20: =I20+I20*8% -> 566870.4 | K20: =J20+J20*8% -> 612220.03 | L20: =SUM(G20:K20) -> 2639970.4
A21: Outlet staff salary (Permanent) | B21: =SUM(INFORMATION!E7) -> 1 | C21: =SUM(INFORMATION!G7:G8) -> 23000 | D21: =C21 -> 23000 | E21: =D21 -> 23000 | G21: =SUM(C21:E21)*4 -> 276000 | H21: =G21+G21*8% -> 298080 | I21: =H21+H21*8% -> 321926.4 | J21: =I21+I21*8% -> 347680.51 | K21: =J21+J21*8% -> 375494.95 | L21: =SUM(G21:K21) -> 1619181.9
A22: Outlet staff salary (Support team) | C22: 0 | D22: =C22 -> 0 | E22: =D22 -> 0 | L22: =SUM(G22:K22) -> 0
A23: Depreciation | C23: =(C3*0.7)/60 -> 3850 | D23: =C23 -> 3850 | E23: =D23 -> 3850 | G23: =SUM(C23:E23)*4 -> 46200 | H23: =G23 -> 46200 | I23: =H23 -> 46200 | J23: =I23 -> 46200 | K23: =J23 -> 46200 | L23: =SUM(G23:K23) -> 231000
A24: Consumption-Consumable | B24: =IF('Sales forecasting tools'!C20="Y",0.8%,0.65%) -> 0.0065 | C24: =$B$24*C10 -> 11700 | D24: =$B$24*D10 -> 11700 | E24: =$B$24*E10 -> 11700 | G24: =$B$24*G10 -> 140400 | H24: =$B$24*H10 -> 157248 | I24: =$B$24*I10 -> 172972.8 | J24: =$B$24*J10 -> 190270.08 | K24: =$B$24*K10 -> 205491.69 | L24: =SUM(G24:K24) -> 866382.57
A25: Electricity & Utility | C25: 0 | D25: 0 | E25: 0 | L25: =SUM(G25:K25) -> 0
A26: Product Wastage | B26: =INFORMATION!B14 -> N | C26: =IF($B$26="Y",(C10*0.23%),(C10*0.06%)) -> 1080 | D26: =IF($B$26="Y",(D10*0.58%),0) -> 0 | E26: =IF($B$26="Y",(E10*0.58%),0) -> 0 | G26: =IF($B$26="Y",(G10*0.58%),0) -> 0 | H26: =IF($B$26="Y",(H10*0.58%),0) -> 0 | I26: =IF($B$26="Y",(I10*0.58%),0) -> 0 | J26: =IF($B$26="Y",(J10*0.58%),0) -> 0 | K26: =IF($B$26="Y",(K10*0.58%),0) -> 0 | L26: =SUM(G26:K26) -> 0
A27: Maintenance | C27: 0 | D27: 0 | E27: 0 | L27: =SUM(G27:K27) -> 0
A28: Security | B28: =INFORMATION!E21 -> 0 | C28: =INFORMATION!G21 -> 0 | D28: =C28 -> 0 | E28: =D28 -> 0 | G28: =SUM(C28:E28)*4 -> 0 | H28: =G28*108% -> 0 | I28: =H28*108% -> 0 | J28: =I28*108% -> 0 | K28: =J28*108% -> 0 | L28: =SUM(G28:K28) -> 0
A29: Generator Running Expense | G29: =SUM(C29:E29)*4 -> 0 | H29: =G29+G29*5% -> 0 | I29: =H29+H29*5% -> 0 | J29: =I29+I29*5% -> 0 | K29: =J29+J29*5% -> 0 | L29: =SUM(G29:K29) -> 0
A30: Cleaning | B30: =INFORMATION!E22 -> 0 | C30: =INFORMATION!G22 -> 0 | D30: =C30 -> 0 | E30: =D30 -> 0 | G30: =SUM(C30:E30)*4 -> 0 | H30: =G30*108% -> 0 | I30: =H30*108% -> 0 | J30: =I30*108% -> 0 | K30: =J30*108% -> 0 | L30: =SUM(G30:K30) -> 0
A31: Outlet operational Expense | C31: 25000 | D31: 5000 | E31: =D31 -> 5000 | G31: =E31*11+C31 -> 80000 | H31: =(E31*12)*105% -> 63000 | I31: =H31*105% -> 66150 | J31: =I31*105% -> 69457.5 | K31: =J31*105% -> 72930.375 | L31: =SUM(G31:K31) -> 351537.88
A32: Connectivity Charge | B32: =INFORMATION!B18 -> N | C32: =IF(B32="Y",6500,4500) -> 4500 | D32: =C32 -> 4500 | E32: =D32 -> 4500 | G32: =SUM(C32:E32)*4 -> 54000 | H32: =G32 -> 54000 | I32: =H32 -> 54000 | J32: =I32 -> 54000 | K32: =J32 -> 54000 | L32: =SUM(G32:K32) -> 270000
A33: Membership Discount | B33: 0.0025 | C33: =$B$33*C10 -> 4500 | D33: =$B$33*D10 -> 4500 | E33: =$B$33*E10 -> 4500 | G33: =$B$33*G10 -> 54000 | H33: =$B$33*H10 -> 60480 | I33: =$B$33*I10 -> 66528 | J33: =$B$33*J10 -> 73180.8 | K33: =$B$33*K10 -> 79035.264 | L33: =SUM(G33:K33) -> 333224.06
A34: Insurance Charges | C34: 2500 | D34: =C34 -> 2500 | E34: =D34 -> 2500 | G34: =SUM(C34:E34)*4 -> 30000 | H34: =G34 -> 30000 | I34: =H34 -> 30000 | J34: =I34 -> 30000 | K34: =J34 -> 30000 | L34: =SUM(G34:K34) -> 150000
A35: Promotional Expense | C35: 0 | D35: =C35 -> 0 | E35: =D35 -> 0 | G35: =SUM(C35:E35)*4 -> 0 | H35: =G35 -> 0 | I35: =H35 -> 0 | J35: =I35 -> 0 | K35: =J35 -> 0 | L35: =SUM(G35:K35) -> 0
A36: Ice Expenses | B36: =B26 -> N | C36: =IF(B36="Y",C10*0.5%,"") | D36: =IF(B36="Y",D10*0.5%,"") | E36: =IF(B36="Y",E10*0.5%,"") | G36: =SUM(C36:E36)*4 -> 0 | H36: =G36*105% -> 0 | I36: =H36*105% -> 0 | J36: =I36*105% -> 0 | K36: =J36*105% -> 0 | L36: =SUM(G36:K36) -> 0
A37: Denomination charge | B37: 0.0003 | C37: =$B$37*C10 -> 540 | D37: =$B$37*D10 -> 540 | E37: =$B$37*E10 -> 540 | G37: =$B$37*G10 -> 6480 | H37: =$B$37*H10 -> 7257.6 | I37: =$B$37*I10 -> 7983.36 | J37: =$B$37*J10 -> 8781.696 | K37: =$B$37*K10 -> 9484.2317 | L37: =SUM(G37:K37) -> 39986.888
A38: Credit card charge | B38: 0.003 | C38: =$B$38*C10 -> 5400 | D38: =$B$38*D10 -> 5400 | E38: =$B$38*E10 -> 5400 | G38: =$B$38*G10 -> 64800 | H38: =$B$38*H10 -> 72576 | I38: =$B$38*I10 -> 79833.6 | J38: =$B$38*J10 -> 87816.96 | K38: =$B$38*K10 -> 94842.317 | L38: =SUM(G38:K38) -> 399868.88
A39: Conveyance Expenses | C39: 4000 | D39: =C39 -> 4000 | E39: =D39 -> 4000 | G39: =SUM(C39:E39)*4 -> 48000 | H39: =G39*105% -> 50400 | I39: =H39*105% -> 52920 | J39: =I39*105% -> 55566 | K39: =J39*105% -> 58344.3 | L39: =SUM(G39:K39) -> 265230.3
A40: Printing and Stationary | C40: 2500 | D40: =C40 -> 2500 | E40: =D40 -> 2500 | G40: =SUM(C40:E40)*4 -> 30000 | H40: =G40*105% -> 31500 | I40: =H40*105% -> 33075 | J40: =I40*105% -> 34728.75 | K40: =J40*105% -> 36465.188 | L40: =SUM(G40:K40) -> 165768.94
A41: Entertainment | C41: 1000 | D41: =C41 -> 1000 | E41: =D41 -> 1000 | G41: =SUM(C41:E41)*4 -> 12000 | H41: =G41*105% -> 12600 | I41: =H41*105% -> 13230 | J41: =I41*105% -> 13891.5 | K41: =J41*105% -> 14586.075 | L41: =SUM(G41:K41) -> 66307.575
A42: Stock write off (Prov.) | B42: =VLOOKUP('Sales forecasting tools'!$N$21,'Sales forecasting tools'!$AB:$AE,4,0) -> 0.0048407649 | C42: =$B$42*C10 -> 8713.3769 | D42: =$B$42*D10 -> 8713.3769 | E42: =$B$42*E10 -> 8713.3769 | G42: =$B$42*G10 -> 104560.52 | H42: =$B$42*H10 -> 117107.78 | I42: =$B$42*I10 -> 128818.56 | J42: =$B$42*J10 -> 141700.42 | K42: =$B$42*K10 -> 153036.45 | L42: =SUM(G42:K42) -> 645223.74
...

Sheet MANPOWER
C1: Non-PNP | D1: Non-PNP | E1: Non-PNP | F1: Non-PNP | G1: Non-PNP | H1: Non-PNP | I1: Non-PNP | J1: Non-PNP | K1: Non-PNP | L1: Non-PNP | M1: Non-PNP | N1: Non-PNP | O1: Non-PNP | P1: Non-PNP | Q1: Non-PNP | R1: Non-PNP
C2: =SUM(C4:C17) -> 4 | D2: =SUM(D4:D17) -> 5 | E2: =SUM(E4:E17) -> 6 | F2: =SUM(F4:F17) -> 8 | G2: =SUM(G4:G17) -> 9 | H2: =SUM(H4:H17) -> 10 | I2: =SUM(I4:I17) -> 12 | J2: =SUM(J4:J17) -> 13 | ... R2: =SUM(R4:R17) -> 0
C3: Below 15 Lac | D3: 15 - 18 Lac | E3: 19 - 21 Lac | F3: 22 - 24 Lac | G3: 25 - 27 Lac | H3: 28 - 30 Lac | I3: 31 - 33 Lac | J3: 34 - 36 Lac | K3: 37 - 39 Lac | L3: 40 - 42 Lac | M3: 43 - 45 Lac | N3: 46 - 48 Lac | O3: 49 - 51 Lac | P3: 52 - 54 Lac | Q3: 55 - 57 Lac | R3: 58 - 60 Lac | S3: 61 - 63 Lac | T3: 64 - 66 Lac | U3: 67 - 69 Lac | V3: 70 - 72 Lac | W3: 73 - 75 Lac | X3: 76 - 78 Lac | Y3: 79 - 81 Lac | Z3: 82 - 84 Lac | AA3: 85 - 87 Lac | AB3: 88 - 90 Lac | AC3: 91 - 93 Lac | AD3: 94 - 96 Lac | AE3: 97 - 99 Lac | AF3: 1 Cr
B4: OM-Parmanent | C4: 1 | D4: 1 | E4: 1 | F4: 1 | G4: 1 | H4: 1 | I4: 1 | J4: 1 | K4: 1 | L4: 1 | M4: 1 | N4: 1 | O4: 1
B5: ICMO-Parmanent
B6: Duty officer | C6: 1 | D6: 1 | E6: 1 | F6: 1 | G6: 1 | H6: 1 | I6: 1 | J6: 1 | K6: 1 | L6: 1 | M6: 1 | N6: 1 | O6: 1
B7: CG | C7: 1 | D7: 2 | E7: 2 | F7: 4 | G7: 5 | H7: 4 | I7: 4 | J7: 5 | K7: 5 | L7: 6 | M7: 6 | N7: 7 | O7: 7
B8: COMMODITY | H8: 1 | I8: 1 | J8: 1 | K8: 1 | L8: 1 | M8: 2 | N8: 2 | O8: 2
B9: PROTEIN
B10: PERISHABLES
B11: GM & LIFESTYLE
B12: POS | C12: 1 | D12: 1 | E12: 2 | F12: 2 | G12: 2 | H12: 2 | I12: 2 | J12: 2 | K12: 2 | L12: 2 | M12: 2 | N12: 2 | O12: 2
B13: PORTER
B14: BSM | I14: 1 | J14: 1 | K14: 1 | L14: 1 | M14: 1 | N14: 1 | O14: 1
B15: BK STR | H15: 1 | I15: 2 | J15: 2 | K15: 3 | L15: 3 | M15: 3 | N15: 3 | O15: 4
B16: SECURITY
B17: CLEANER
C18: =C3&C1 -> Below 15 LacNon-PNP | D18: =D3&D1 -> 15 - 18 LacNon-PNP | E18: =E3&E1 -> 19 - 21 LacNon-PNP | F18: =F3&F1 -> 22 - 24 LacNon-PNP | G18: =G3&G1 -> 25 - 27 LacNon-PNP | H18: =H3&H1 -> 28 - 30 LacNon-PNP | I18: =I3&I1 -> 31 - 33 LacNon-PNP | J18: =J3&J1 -> 34 - 36 LacNon-PNP | ... O18: =O3&O1 -> 49 - 51 LacNon-PNP
C22: PNP | D22: PNP | E22: PNP | F22: PNP | G22: PNP | H22: PNP | I22: PNP | J22: PNP | K22: PNP | L22: PNP | M22: PNP | N22: PNP | O22: PNP | P22: PNP | Q22: PNP | R22: PNP | S22: PNP | T22: PNP | U22: PNP | V22: PNP | W22: PNP | X22: PNP | Y22: PNP | Z22: PNP | AA22: PNP | AB22: PNP | AC22: PNP | AD22: PNP | AE22: PNP
C23: =SUM(C25:C36,C38) -> 0 | D23: =SUM(D25:D36,D38) -> 0 | E23: =SUM(E25:E36,E38) -> 0 | F23: =SUM(F25:F36,F38) -> 0 | G23: =SUM(G25:G36,G38) -> 14 | H23: =SUM(H25:H36,H38) -> 16 | I23: =SUM(I25:I36,I38) -> 17 | J23: =SUM(J25:J36,J38) -> 17 | ... AE23: =SUM(AE25:AE36,AE38) -> 33
C24: Below 15 Lac | D24: 15 - 18 Lac | E24: 19 - 21 Lac | F24: 22 - 24 Lac | G24: 25 - 27 Lac | H24: 28 - 30 Lac | I24: 31 - 33 Lac | J24: 34 - 36 Lac | K24: 37 - 39 Lac | L24: 40 - 42 Lac | M24: 43 - 45 Lac | N24: 46 - 48 Lac | O24: 49 - 51 Lac | P24: 52 - 54 Lac | Q24: 55 - 57 Lac | R24: 58 - 60 Lac | S24: 61 - 63 Lac | T24: 64 - 66 Lac | U24: 67 - 69 Lac | V24: 70 - 72 Lac | W24: 73 - 75 Lac | X24: 76 - 78 Lac | Y24: 79 - 81 Lac | Z24: 82 - 84 Lac | AA24: 85 - 87 Lac | AB24: 88 - 90 Lac | AC24: 91 - 93 Lac | AD24: 94 - 96 Lac | AE24: 97 - 99 Lac | AF24: 1 Cr
B25: OM-Parmanent | G25: 1 | H25: 1 | I25: 1 | J25: 1 | K25: 1 | L25: 1 | M25: 1 | N25: 1 | O25: 1 | P25: 1 | Q25: 1 | R25: 1 | S25: 1 | T25: 1 | U25: 1 | V25: 1 | W25: 1 | X25: 1 | Y25: 1 | Z25: 1 | AA25: 1 | AB25: 1 | AC25: 1 | AD25: 1 | AE25: 1
B26: ICMO-Parmanent | G26: 1 | H26: 1 | I26: 1 | J26: 1 | K26: 1 | L26: 1 | M26: 1 | N26: 1 | O26: 1 | P26: 1 | Q26: 1 | R26: 1 | S26: 1 | T26: 1 | U26: 1 | V26: 1 | W26: 1 | X26: 1 | Y26: 1 | Z26: 1 | AA26: 1 | AB26: 1 | AC26: 1 | AD26: 1 | AE26: 1
B27: Duty officer
B28: CG | G28: 2 | H28: 4 | I28: 5 | J28: 4 | K28: 4 | L28: 5 | M28: 5 | N28: 6 | O28: 6 | P28: 7 | Q28: 7 | R28: 7 | S28: 7 | T28: 7 | U28: 7 | V28: 7 | W28: 7 | X28: 7 | Y28: 8 | Z28: 8 | AA28: 8 | AB28: 8 | AC28: 8 | AD28: 8 | AE28: 8
B29: COMMODITY | J29: 1 | K29: 1 | L29: 1 | M29: 1 | N29: 1 | O29: 2 | P29: 2 | Q29: 2 | R29: 2 | S29: 2 | T29: 2 | U29: 2 | V29: 3 | W29: 3 | X29: 3 | Y29: 3 | Z29: 3 | AA29: 3 | AB29: 3 | AC29: 3 | AD29: 3 | AE29: 3
B30: PROTEIN | G30: 4 | H30: 4 | I30: 4 | J30: 4 | K30: 4 | L30: 4 | M30: 4 | N30: 4 | O30: 4 | P30: 4 | Q30: 4 | R30: 4 | S30: 4 | T30: 4 | U30: 5 | V30: 5 | W30: 5 | X30: 5 | Y30: 5 | Z30: 5 | AA30: 5 | AB30: 5 | AC30: 5 | AD30: 5 | AE30: 5
B31: PERISHABLES
B32: GM & LIFESTYLE
B33: POS | G33: 2 | H33: 2 | I33: 2 | J33: 2 | K33: 3 | L33: 3 | M33: 3 | N33: 3 | O33: 3 | P33: 3 | Q33: 3 | R33: 3 | S33: 3 | T33: 3 | U33: 4 | V33: 4 | W33: 4 | X33: 4 | Y33: 5 | Z33: 5 | AA33: 5 | AB33: 5 | AC33: 5 | AD33: 5 | AE33: 5
B34: PORTER
B35: BSM | K35: 1 | L35: 1 | M35: 1 | N35: 1 | O35: 1 | P35: 1 | Q35: 1 | R35: 1 | S35: 1 | T35: 1 | U35: 1 | V35: 1 | W35: 1 | X35: 1 | Y35: 1 | Z35: 1 | AA35: 1 | AB35: 1 | AC35: 1 | AD35: 1 | AE35: 1
B36: BK STR | G36: 2 | H36: 2 | I36: 2 | J36: 2 | K36: 2 | L36: 2 | M36: 3 | N36: 3 | O36: 3 | P36: 3 | Q36: 4 | R36: 4 | S36: 4 | T36: 4 | U36: 4 | V36: 4 | W36: 4 | X36: 4 | Y36: 4 | Z36: 4 | AA36: 4 | AB36: 4 | AC36: 4 | AD36: 4 | AE36: 4
B37: SECURITY | G37: 1 | H37: 1 | I37: 1 | J37: 1 | K37: 1 | L37: 1 | M37: 1 | N37: 1 | O37: 1 | P37: 1 | Q37: 1 | R37: 2 | S37: 2 | T37: 2 | U37: 2 | V37: 2 | W37: 2 | X37: 2 | Y37: 2 | Z37: 2 | AA37: 2 | AB37: 2 | AC37: 2 | AD37: 2 | AE37: 2
B38: CLEANER | G38: 2 | H38: 2 | I38: 2 | J38: 2 | K38: 2 | L38: 2 | M38: 2 | N38: 2 | O38: 2 | P38: 2 | Q38: 2 | R38: 4 | S38: 4 | T38: 4 | U38: 4 | V38: 4 | W38: 4 | X38: 5 | Y38: 5 | Z38: 5 | AA38: 5 | AB38: 5 | AC38: 5 | AD38: 5 | AE38: 5
C39: =C24&C22 -> Below 15 LacPNP | D39: =D24&D22 -> 15 - 18 LacPNP | E39: =E24&E22 -> 19 - 21 LacPNP | F39: =F24&F22 -> 22 - 24 LacPNP | G39: =G24&G22 -> 25 - 27 LacPNP | H39: =H24&H22 -> 28 - 30 LacPNP | I39: =I24&I22 -> 31 - 33 LacPNP | J39: =J24&J22 -> 34 - 36 LacPNP | ... AE39: =AE24&AE22 -> 97 - 99 LacPNP

Sheet Outlet Data
A1: SL No | B1: CODE | C1: Outlet Name | D1: LOOK | E1: LOOK 2 | F1: Look 3 | G1: Look 4 | H1: Lunching Date | I1: SFT | J1: SFT Band | K1: Division | L1: District | M1: PNP Non PNP status | N1: Location Type | O1: Population Density | P1: Income Level | Q1: Location Type (D,T,D) | R1: Dhaka/Out of Dhaka N | S1: Avg Monthly Sales | T1: Sales/SFT | U1: Outlet Own P25 Sales | V1: Outlet Own P75 Sales | W1: Should-be Sales | X1: Benchmark P25 Sales | Y1: Benchmark P75 Sales | Z1: Benchmark Store Count | AA1: Benchmark Level | AB1: Benchmark Criteria Used | AC1: Sales Position | AD1: Gap vs Should-be Sales | AE1: Gap % vs Should-be | AF1: Profit % | AG1: Sales Jan-26 | AH1: Sales Feb-26 | AI1: Sales Mar-26 | AJ1: Sales Apr-26 | AK1: Sales May-26 | AL1: Profit Jan-26 | AM1: Profit Feb-26 | AN1: Profit Mar-26 | AO1: Profit Apr-26 | AP1: Profit May-26 | AQ1: GP AVG | AR1: DV & DI | AS1: Stock write off (Prov.) | AT1: Layout shape | AU1: Floor type | AV1: Status
A2: 0 | B2: D002 | C2: Postogola | D2: =CONCATENATE(J2,K2,L2,M2,,N2,O2,P2,Q2,AT2,AU2) -> 5001 - 5500 SFTDhakaDhakaPNPHigh Street W Residential BlockMCবিভাগীয় শহরL shapeGround floor | E2: =CONCATENATE('Outlet Data'!K2,L2,'Outlet Data'!N2,M2) -> DhakaDhakaHigh Street W Residential BlockPNP | F2: =CONCATENATE(L2,Q2,M2) -> Dhakaবিভাগীয় শহরPNP | G2: =CONCATENATE(L2,M2) -> DhakaPNP | H2: 39749 | I2: 5100 | J2: =IF(I2="","",IF(I2<=1000,"Below 1000 SFT",IF(I2>10000,"More Then 10000 SFT",(INT((I2-1001)/500)*500+1001)&" - "&(INT((I2-1001)/500)*500+1500)&" SFT"))) -> 5001 - 5500 SFT | K2: Dhaka | L2: Dhaka | M2: PNP | N2: High Street W Residential Block | O2: M | P2: C | Q2: বিভাগীয় শহর | R2: Dhaka | S2: 4532111.2 | T2: 888.64925 | U2: 4265797 | V2: 4896351 | W2: 12869518 | X2: 10195629 | Y2: 14771974 | Z2: 24 | AA2: L6 Practical: SFT+PNP+Dhaka | AB2: SFT Band + PNP Non PNP status + Dhaka/Out of Dhaka N | AC2: Below P25 | AD2: -8337406.7 | AE2: -0.64784142 | AF2: 0.045444952 | AG2: 4222622 | AH2: 4265797 | AI2: 5004180 | AJ2: 4271606 | AK2: 4896351 | AL2: 16641.222 | AM2: 191061.98 | AN2: 311253.39 | AO2: 239239.52 | AP2: 271611.77 | AQ2: 0.17508522 | AR2: =K2&L2 -> DhakaDhaka | AS2: 0.011484892 | AT2: L shape | AU2: Ground floor | AV2: OWN
A3: 102 | B3: D004 | C3: Nakhal Para | D3: =CONCATENATE(J3,K3,L3,M3,,N3,O3,P3,Q3,AT3,AU3) -> 2501 - 3000 SFTDhakaDhakaPNPHigh Street W Residential BlockMCবিভাগীয় শহরSquare ⬜ shapeGround floor | E3: =CONCATENATE('Outlet Data'!K3,L3,'Outlet Data'!N3,M3) -> DhakaDhakaHigh Street W Residential BlockPNP | F3: =CONCATENATE(L3,Q3,M3) -> Dhakaবিভাগীয় শহরPNP | G3: =CONCATENATE(L3,M3) -> DhakaPNP | H3: 39814 | I3: 2670 | J3: =IF(I3="","",IF(I3<=1000,"Below 1000 SFT",IF(I3>10000,"More Then 10000 SFT",(INT((I3-1001)/500)*500+1001)&" - "&(INT((I3-1001)/500)*500+1500)&" SFT"))) -> 2501 - 3000 SFT | K3: Dhaka | L3: Dhaka | M3: PNP | N3: High Street W Residential Block | O3: M | P3: C | Q3: বিভাগীয় শহর | R3: Dhaka | S3: 6512140.8 | T3: 2439.004 | U3: 6246545 | V3: 6664462 | W3: 7985832.2 | X3: 5306408.2 | Y3: 10796483 | Z3: 23 | AA3: L6 Practical: SFT+PNP+Dhaka | AB3: SFT Band + PNP Non PNP status + Dhaka/Out of Dhaka N | AC3: Within P25–P75 | AD3: -1473691.4 | AE3: -0.18453824 | AF3: 0.071120974 | AG3: 5790385 | AH3: 6248284 | AI3: 6664462 | AJ3: 6246545 | AK3: 7611028 | AL3: 311332.17 | AM3: 390243.98 | AN3: 458037.27 | AO3: 479242.03 | AP3: 676893.53 | AQ3: 0.17161895 | AR3: =K3&L3 -> DhakaDhaka | AS3: 0.0037810806 | AT3: Square ⬜ shape | AU3: Ground floor | AV3: OWN
